Unhandled exception in thread started by 
sys.excepthook is missing
lost sys.stderr
Exception in thread /niryo_one/kits/conveyor_1_feedback (most likely raised during interpreter shutdown):
Traceback (most recent call last):
  File "/usr/lib/python2.7/threading.py", line 801, in __bootstrap_inner
  File "/usr/lib/python2.7/threading.py", line 754, in run
 Exception in thread /niryo_one/current_tool_id (most likely raised during interpreter shutdown):
Traceback (most recent call last):
 Exception in thread /niryo_one/hardware_status (most likely raised during interpreter shutdown):
Traceback (most recent call last):
  File "/usr/lib/python2.7/threading.py", line 801, in __bootstrap_inner
 