Exception in thread Thread-4 (most likely raised during interpreter shutdown):Exception in thread /niryo_one/commander/robot_action/result (most likely raised during interpreter shutdown):
Traceback (most recent call last):
  File "/usr/lib/python2.7/threading.py", line 801, in __bootstrap_inner
  File "/usr/lib/python2.7/threading.py", line 754, in run
  File "/opt/ros/kinetic/lib/python2.7/dist-packages/rospy/impl/tcpros_pubsub.py", line 185, in robust_connect_subscriber
  File "/opt/ros/kinetic/lib/python2.7/dist-packages/rospy/impl/tcpros_base.py", line 824, in receive_loop
<type 'exceptions.TypeError'>: 'NoneType' object is not callable
Unhandled exception in thread started by 
sys.excepthook is missing
lost sys.stderr
Exception in thread /niryo_one/commander/robot_action/status (most likely raised during interpreter shutdown):
Traceback (most recent call last):
  File "/usr/lib/python2.7/threading.py", line 801, in __bootstrap_inner
  File "/usr/lib/python2.7/threading.py", line 754, in run
  File "/opt/ros/kinetic/lib/python2.7/dist-packages/rospy/impl/tcpros_pubsub.py", line 185, in robust_connect_subscriber
  File "/opt/ros/kinetic/lib/python2.7/dist-packages/rospy/impl/tcpros_base.py", line 824, in receive_loop
<type 'exceptions.TypeError'>: 'NoneType' object is not callable
Exception in thread /niryo_one/learning_mode (most likely raised during interpreter shutdown):
Traceback (most recent call last):
  File "/usr/lib/python2.7/threading.py", line 801, in __bootstrap_inner
  File "/usr/lib/python2.7/threading.py", line 754, in run
  File "/opt/ros/kinetic/lib/python2.7/dist-packages/rospy/impl/tcpros_pubsub.py", line 185, in robust_connect_subscriber
  File "/opt/ros/kinetic/lib/python2.7/dist-packages/rospy/impl/tcpros_base.py", line 824, in receive_loop
<type 'exceptions.TypeError'>: 'NoneType' object is not callable
Exception in thread /niryo_one/commander/robot_action/feedback (most likely raised during interpreter shutdown):Exception in thread /niryo_one/hardware_status (most likely raised during interpreter shutdown):
Traceback (most recent call last):
  File "/usr/lib/python2.7/threading.py", line 801, in __bootstrap_inner
  File "/usr/lib/python2.7/threading.py", line 754, in run
  File "/opt/ros/kinetic/lib/python2.7/dist-packages/rospy/impl/tcpros_pubsub.py", line 185, in robust_connect_subscriber
  File "/opt/ros/kinetic/lib/python2.7/dist-packages/rospy/impl/tcpros_base.py", line 824, in receive_loop
<type 'exceptions.TypeError'>: 'NoneType' object is not callable

Traceback (most recent call last):
  File "/usr/lib/python2.7/threading.py", line 801, in __bootstrap_inner
  File "/usr/lib/python2.7/threading.py", line 754, in run
  File "/opt/ros/kinetic/lib/python2.7/dist-packages/rospy/impl/tcpros_pubsub.py", line 185, in robust_connect_subscriber
  File "/opt/ros/kinetic/lib/python2.7/dist-packages/rospy/impl/tcpros_base.py", line 824, in receive_loop
<type 'exceptions.TypeError'>: 'NoneType' object is not callable

Traceback (most recent call last):
  File "/usr/lib/python2.7/threading.py", line 801, in __bootstrap_inner
  File "/usr/lib/python2.7/threading.py", line 754, in run
  File "/opt/ros/kinetic/lib/python2.7/dist-packages/rospy/impl/tcpros_base.py", line 154, in run
<type 'exceptions.AttributeError'>: 'NoneType' object has no attribute 'timeout'
