Exception in thread Thread-18 (most likely raised during interpreter shutdown):Exception in thread /niryo_one/commander/robot_action/feedback (most likely raised during interpreter shutdown):

Traceback (most recent call last):
  File "/usr/lib/python2.7/threading.py", line 801, in __bootstrap_inner
  File "/usr/lib/python2.7/threading.py", line 754, in run
  File "/usr/lib/python2.7/SocketServer.py", line 600, in process_request_thread
  File "/usr/lib/python2.7/SocketServer.py", line 472, in shutdown_request
<type 'exceptions.AttributeError'>: 'NoneType' object has no attribute 'error'
Unhandled exception in thread started by 
sys.excepthook is missing
lost sys.stderr
Traceback (most recent call last):
  File "/usr/lib/python2.7/threading.py", line 801, in __bootstrap_inner
  File "/usr/lib/python2.7/threading.py", line 754, in run
  File "/opt/ros/kinetic/lib/python2.7/dist-packages/rospy/impl/tcpros_pubsub.py", line 185, in robust_connect_subscriber
  File "/opt/ros/kinetic/lib/python2.7/dist-packages/rospy/impl/tcpros_base.py", line 824, in receive_loop